Workbook

Sheet Danh sách chức năng
A1: DANH SÁCH CÁC CHỨC NĂNG
A2: Tên dự án: | B2: SoLi Food Delivery Platform
A3: Người thực hiện: | B3: Nhóm phát triển SoLi
F4: Nhập dữ liệu | H4: Xuất dữ liệu | J4: Truy vấn | L4: File nội bộ | N4: Giao diện ngoài
A5: STT | B5: Tên chức năng chính | C5: Tên chức năng con | D5: Môi trường triển khai | F5: DANH SÁCH ĐỘ ĐO
D6: Web | E6: Mobile | F6: C1 | G6: W1 | H6: C2 | I6: W2 | J6: C3 | K6: W3 | L6: C4 | M6: W4 | N6: C5 | O6: W5
A7: 1 | B7: Authentication & Access | C7: Sign Up | E7: X | F7: 1 | G7: 4 | H7: 1 | I7: 5 | J7: 0 | K7: 4 | L7: 1 | M7: 10 | N7: 1 | O7: 7
A8: 2 | B8: Authentication & Access | C8: Sign In | D8: X | E8: X | F8: 1 | G8: 4 | H8: 1 | I8: 5 | J8: 0 | K8: 4 | L8: 0 | M8: 10 | N8: 0 | O8: 7
A9: 3 | B9: Authentication & Access | C9: Sign Out | D9: X | E9: X | F9: 1 | G9: 4 | H9: 1 | I9: 5 | J9: 0 | K9: 4 | L9: 0 | M9: 10 | N9: 0 | O9: 7
A10: 4 | B10: Authentication & Access | C10: Forgot Password / Send OTP | D10: X | E10: X | F10: 1 | G10: 4 | H10: 1 | I10: 5 | J10: 0 | K10: 4 | L10: 0 | M10: 10 | N10: 1 | O10: 7
A11: 5 | B11: Authentication & Access | C11: Reset Password | D11: X | E11: X | F11: 1 | G11: 4 | H11: 1 | I11: 5 | J11: 0 | K11: 4 | L11: 1 | M11: 10 | N11: 0 | O11: 7
A12: 6 | B12: Authentication & Access | C12: Verify Phone OTP | E12: X | F12: 1 | G12: 4 | H12: 1 | I12: 5 | J12: 0 | K12: 4 | L12: 1 | M12: 10 | N12: 1 | O12: 7
A13: 7 | B13: Authentication & Access | C13: Get Session / Refresh | D13: X | E13: X | F13: 0 | G13: 4 | H13: 1 | I13: 5 | J13: 1 | K13: 4 | L13: 0 | M13: 10 | N13: 0 | O13: 7
A14: 8 | B14: User Profile | C14: View Profile | D14: X | E14: X | F14: 0 | G14: 4 | H14: 0 | I14: 5 | J14: 1 | K14: 4 | L14: 0 | M14: 10 | N14: 0 | O14: 7
A15: 9 | B15: User Profile | C15: Update Profile | D15: X | E15: X | F15: 1 | G15: 4 | H15: 1 | I15: 5 | J15: 0 | K15: 4 | L15: 1 | M15: 10 | N15: 0 | O15: 7
A16: 10 | B16: User Profile | C16: Upload Avatar | D16: X | E16: X | F16: 1 | G16: 4 | H16: 1 | I16: 5 | J16: 0 | K16: 4 | L16: 0 | M16: 10 | N16: 1 | O16: 7
A17: 11 | B17: User Profile | C17: Manage Delivery Addresses | E17: X | F17: 1 | G17: 4 | H17: 1 | I17: 5 | J17: 1 | K17: 4 | L17: 1 | M17: 10 | N17: 0 | O17: 7
A18: 12 | B18: Restaurant Discovery | C18: Browse Restaurant List | E18: X | F18: 0 | G18: 4 | H18: 0 | I18: 5 | J18: 1 | K18: 4 | L18: 0 | M18: 10 | N18: 0 | O18: 7
A19: 13 | B19: Restaurant Discovery | C19: View Restaurant Detail | E19: X | F19: 0 | G19: 4 | H19: 0 | I19: 5 | J19: 1 | K19: 4 | L19: 0 | M19: 10 | N19: 0 | O19: 7
A20: 14 | B20: Restaurant Discovery | C20: Search Restaurants | E20: X | F20: 1 | G20: 4 | H20: 0 | I20: 5 | J20: 1 | K20: 4 | L20: 0 | M20: 10 | N20: 0 | O20: 7
A21: 15 | B21: Restaurant Discovery | C21: Filter / Sort Restaurants | E21: X | F21: 1 | G21: 4 | H21: 0 | I21: 5 | J21: 1 | K21: 4 | L21: 0 | M21: 10 | N21: 0 | O21: 7
A22: 16 | B22: Restaurant Discovery | C22: View Menu & Categories | E22: X | F22: 0 | G22: 4 | H22: 0 | I22: 5 | J22: 1 | K22: 4 | L22: 0 | M22: 10 | N22: 0 | O22: 7
A23: 17 | B23: Restaurant Discovery | C23: View Menu Item Detail | E23: X | F23: 0 | G23: 4 | H23: 0 | I23: 5 | J23: 1 | K23: 4 | L23: 0 | M23: 10 | N23: 0 | O23: 7
A24: 18 | B24: Restaurant Discovery | C24: Check Delivery Zone Coverage | E24: X | F24: 1 | G24: 4 | H24: 1 | I24: 5 | J24: 1 | K24: 4 | L24: 0 | M24: 10 | N24: 0 | O24: 7
A25: 19 | B25: Cart & Checkout | C25: Add Item To Cart | E25: X | F25: 1 | G25: 4 | H25: 1 | I25: 5 | J25: 0 | K25: 4 | L25: 1 | M25: 10 | N25: 0 | O25: 7
A26: 20 | B26: Cart & Checkout | C26: Update Cart Item Quantity | E26: X | F26: 1 | G26: 4 | H26: 1 | I26: 5 | J26: 0 | K26: 4 | L26: 1 | M26: 10 | N26: 0 | O26: 7
A27: 21 | B27: Cart & Checkout | C27: Remove Cart Item | E27: X | F27: 1 | G27: 4 | H27: 1 | I27: 5 | J27: 0 | K27: 4 | L27: 1 | M27: 10 | N27: 0 | O27: 7
A28: 22 | B28: Cart & Checkout | C28: View Cart | E28: X | F28: 0 | G28: 4 | H28: 0 | I28: 5 | J28: 1 | K28: 4 | L28: 0 | M28: 10 | N28: 0 | O28: 7
... A33: 27 | B33: Payment | C33: Initiate VNPay Payment | E33: X | F33: 1 | G33: 4 | H33: 1 | I33: 5 | J33: 0 | K33: 4 | L33: 1 | M33: 10 | N33: 1 | O33: 7
A34: 28 | B34: Payment | C34: Process VNPay IPN | F34: 1 | G34: 4 | H34: 1 | I34: 5 | J34: 0 | K34: 4 | L34: 1 | M34: 10 | N34: 1 | O34: 7
A35: 29 | B35: Payment | C35: Handle VNPay Return URL | E35: X | F35: 0 | G35: 4 | H35: 1 | I35: 5 | J35: 1 | K35: 4 | L35: 1 | M35: 10 | N35: 1 | O35: 7
A36: 30 | B36: Payment | C36: Payment Timeout Auto-Cancel | F36: 0 | G36: 4 | H36: 1 | I36: 5 | J36: 0 | K36: 4 | L36: 1 | M36: 10 | N36: 0 | O36: 7
A37: 31 | B37: Payment | C37: Refund (Admin) | D37: X | F37: 1 | G37: 4 | H37: 1 | I37: 5 | J37: 0 | K37: 4 | L37: 1 | M37: 10 | N37: 1 | O37: 7
A38: 32 | B38: Payment | C38: View Payment History | D38: X | E38: X | F38: 0 | G38: 4 | H38: 0 | I38: 5 | J38: 1 | K38: 4 | L38: 0 | M38: 10 | N38: 0 | O38: 7
A39: 33 | B39: Order (Customer) | C39: View Order History | E39: X | F39: 0 | G39: 4 | H39: 0 | I39: 5 | J39: 1 | K39: 4 | L39: 0 | M39: 10 | N39: 0 | O39: 7
A40: 34 | B40: Order (Customer) | C40: View Order Detail | E40: X | F40: 0 | G40: 4 | H40: 0 | I40: 5 | J40: 1 | K40: 4 | L40: 0 | M40: 10 | N40: 0 | O40: 7
A41: 35 | B41: Order (Customer) | C41: Track Order Status (Realtime) | E41: X | F41: 0 | G41: 4 | H41: 1 | I41: 5 | J41: 1 | K41: 4 | L41: 0 | M41: 10 | N41: 1 | O41: 7
A42: 36 | B42: Order (Customer) | C42: Cancel Order | E42: X | F42: 1 | G42: 4 | H42: 1 | I42: 5 | J42: 0 | K42: 4 | L42: 1 | M42: 10 | N42: 0 | O42: 7
A43: 37 | B43: Order (Customer) | C43: Reorder | E43: X | F43: 1 | G43: 4 | H43: 1 | I43: 5 | J43: 1 | K43: 4 | L43: 1 | M43: 10 | N43: 0 | O43: 7
A44: 38 | B44: Notification | C44: Receive In-App Notification | D44: X | E44: X | F44: 0 | G44: 4 | H44: 1 | I44: 5 | J44: 0 | K44: 4 | L44: 1 | M44: 10 | N44: 0 | O44: 7
...

Sheet Hệ số hiệu chỉnh
A1: STT | B1: Câu hỏi (Yếu tố kỹ thuật) | C1: Điểm (Fi) | D1: Lý do chọn
A2: 1 | B2: Bảo đảm an toàn khi cập nhật & truyền dữ liệu? | C2: 5 | D2: Thanh toán VNPay (HMAC SHA512), Better Auth bearer session, idempotency keys, HTTPS, PII hồ sơ người dùng + địa chỉ giao hàng.
A3: 2 | B3: Có đòi hỏi truyền thông không? | C3: 4 | D3: Mobile + Web + Backend giao tiếp REST; Socket.IO realtime cho /notifications và trạng thái đơn; webhook IPN từ VNPay; FCM push.
A4: 3 | B4: Có xử lý phân bố không? | C4: 3 | D4: Modular monolith + PostgreSQL + Redis/Valkey + Cloudinary + VNPay; nhiều client (mobile, web).
A5: 4 | B5: Tốc độ có quan trọng không? | C5: 4 | D5: ASR ràng buộc: tìm kiếm/danh sách p95 ≤ 2s; cập nhật trạng thái ≤ 5s; xử lý đơn vào giờ cao điểm.
A6: 5 | B6: Có đòi hỏi cấu hình mạnh? | C6: 3 | D6: Cần DB + Redis + worker timeout ổn định; Render free tier giới hạn nên phải tối ưu kết nối, pool.
A7: 6 | B7: Nhập dữ liệu có transaction? | C7: 5 | D7: Place Order (CQRS) đa bước: trừ kho/khoá Redis, áp khuyến mãi, ghi đơn, gọi VNPay; transition trạng thái dùng state machine + transaction.
A8: 7 | B8: Dữ liệu lưu trữ cập nhật trực tuyến? | C8: 5 | D8: Trạng thái đơn, giỏ hàng, snapshot ACL, inbox thông báo đều update online; projector cập nhật ngay khi nhà hàng/menu/zone thay đổi.
A9: 8 | B9: Nhập/xuất/truy vấn phức tạp? | C9: 4 | D9: Tìm kiếm theo khoảng cách/zone, filter nhiều tiêu chí, lịch sử đơn theo role, báo cáo doanh thu, Kanban cho nhà hàng.
A10: 9 | B10: Xử lý bên trong phức tạp? | C10: 4 | D10: State machine đơn hàng, pricing engine khuyến mãi (preview/reserve/confirm/rollback), reconcile thanh toán, ACL snapshot, quiet-hours.
A11: 10 | B11: Mã nguồn cần thiết kế dùng lại? | C11: 4 | D11: Port/Adapter (PAYMENT_INITIATION_PORT, PROMOTION_APPLICATION_PORT), kênh thông báo (in-app/push/email) trừu tượng qua interface, EventBus.
A12: 11 | B12: Chuyển đổi dữ liệu & cài đặt có phức tạp? | C12: 3 | D12: Drizzle migrations + seed (catalog, zones), cấu hình CI/CD GitHub Actions + GHCR + Render IaC (Terraform).
A13: 12 | B13: Dễ thay đổi & dễ dùng? | C13: 4 | D13: Người dùng cuối là khách hàng phổ thông + nhân viên nhà hàng; UI bằng tiếng Việt; mobile-first; cấu hình kênh thông báo linh hoạt.
B14: Tổng ΣFi | C14: =SUM(C2:C13) -> 48
B15: VAF = 0.65 + 0.01 × ΣFi | C15: =0.65+0.01*C14 -> 1.13

Sheet Công nghệ triển khai
A1: CÔNG NGHỆ TRIỂN KHAI - SoLi Food Delivery Platform
A3: STT | B3: Hạng mục | C3: Công nghệ | D3: Ghi chú
A4: 1 | B4: Frontend Web | C4: React 18 + Vite + TypeScript + TailwindCSS + shadcn/ui | D4: Dashboard nhà hàng và quản trị; build production ra Nginx Docker image.
A5: 2 | B5: Frontend Mobile | C5: React Native (Expo) + NativeWind + Expo Router | D5: Ứng dụng khách hàng; EAS Build phát hành Android. iOS sẵn sàng.
A6: 3 | B6: Backend | C6: NestJS 10 + TypeScript (Node.js LTS) | D6: Modular monolith; module bounded contexts: auth, restaurant-catalog, ordering, payment, promotion, notification, image.
A7: 4 | B7: Kiến trúc | C7: Modular Monolith + Selective CQRS + EventBus nội bộ | D7: PlaceOrderCommand, TransitionOrderCommand, ProcessIpnCommand; in-process EventBus + handler.
A8: 5 | B8: ACL / Anti-Corruption | C8: Snapshot Projector + Repository | D8: menu-item, restaurant, delivery-zone snapshots cho Ordering; restaurant snapshot cho Notification.
A9: 6 | B9: Cơ sở dữ liệu | C9: PostgreSQL 16 + Drizzle ORM | D9: Migration bằng drizzle-kit; schema khai báo TypeScript-first.
A10: 7 | B10: Cache / Realtime State | C10: Redis / Valkey | D10: Giỏ hàng, idempotency keys, distributed lock, presence, rate limit.
A11: 8 | B11: Realtime Push | C11: Socket.IO (/notifications namespace) | D11: Cập nhật trạng thái đơn, thông báo trong app, theo dõi shipper.
A12: 9 | B12: Xác thực | C12: Better Auth (bearer session) + Admin plugin + Phone OTP | D12: Vai trò: admin, restaurant, shipper, user; OTP qua nhà cung cấp SMS.
A13: 10 | B13: Thanh toán | C13: VNPay (URL build + IPN + Return URL) — HMAC SHA512 | D13: Refund stub cho dev; sẵn sàng tích hợp endpoint refund thật.
A14: 11 | B14: Lưu trữ ảnh | C14: Cloudinary (signed upload) | D14: Hình ảnh menu, ảnh đại diện; URL chuẩn hoá lưu trong DB.
A15: 12 | B15: Push Notification | C15: Firebase Cloud Messaging (FCM v1 API) | D15: Có Stub provider cho môi trường dev/test.
... A25: 22 | B25: Quản lý phụ thuộc | C25: pnpm workspaces + Turborepo | D25: Monorepo apps/api, apps/web, apps/mobile, infra/render, tools.

Sheet Danh mục chi phí
A1: TỔNG CHI PHÍ PHÁT TRIỂN PHẦN MỀM - SoLi Food Delivery
A3: Tham số đầu vào
A4: Tổng UFP | C4: ='Danh sách chức năng'!C85 -> 1262 | D4: FP
A5: ΣFi | C5: ='Hệ số hiệu chỉnh'!C14 -> 48
A6: VAF | C6: ='Hệ số hiệu chỉnh'!C15 -> 1.13
A7: AFP (FP đã hiệu chỉnh) | C7: ='Danh sách chức năng'!C88 -> 1426.06 | D7: FP
A8: Chi phí trả mỗi người/tháng | C8: 1500 | D8: USD
A9: Năng suất giả định | C9: 8 | D9: FP/pm
A10: Chi phí mỗi FP | C10: =C8/C9 -> 187.5 | D10: USD/FP
A11: Quy ra đơn vị pm | C11: =C7/C9 -> 178.2575 | D11: pm
A12: Tổng chi phí dự án (gross) | C12: =C7*C10 -> 267386.25 | D12: USD
A15: Danh mục chi phí | B15: Tỷ lệ | C15: Thành tiền (USD) | D15: Diễn giải
A16: Chi phí BA (Business Analysis) | B16: 0.08 | C16: =B16*C12 -> 21390.9 | D16: Khảo sát, UC, BRD, business rules, user stories.
A17: Chi phí Architecture & Design | B17: 0.1 | C17: =B17*C12 -> 26738.625 | D17: ASR, ADD, ADR, SAD; thiết kế module/CQRS/ACL; bản vẽ PlantUML.
A18: Chi phí Development | B18: 0.45 | C18: =B18*C12 -> 120323.81 | D18: Backend NestJS, Web React, Mobile React Native, tích hợp VNPay/FCM/Cloudinary.
A19: Chi phí Testing & QA | B19: 0.15 | C19: =B19*C12 -> 40107.938 | D19: Unit, integration, e2e, kịch bản thanh toán/IPN, hồi quy.
A20: Chi phí Deployment & DevOps | B20: 0.05 | C20: =B20*C12 -> 13369.312 | D20: Docker, GHCR, Render IaC, GitHub Actions pipelines.
A21: Chi phí Training & Hỗ trợ | B21: 0.03 | C21: =B21*C12 -> 8021.5875 | D21: Tài liệu sử dụng cho nhà hàng, video hướng dẫn ≤5 phút.
A22: Chi phí Documentation | B22: 0.07 | C22: =B22*C12 -> 18717.037 | D22: Tài liệu kỹ thuật, sổ tay vận hành, tài liệu API.
A23: Chi phí Dự phòng (Reserve) | B23: 0.07 | C23: =B23*C12 -> 18717.037 | D23: Rủi ro tích hợp, thay đổi yêu cầu, mở rộng giai đoạn 2.
A24: TỔNG CỘNG | B24: =SUM(B16:B23) -> 1 | C24: =SUM(C16:C23) -> 267386.25
